2022-03-23 17:28:24,227 INFO    MainThread:22852 [internal.py:wandb_internal():92] W&B internal server running at pid: 22852, started at: 2022-03-23 17:28:24.226438
2022-03-23 17:28:24,228 INFO    WriterThread:22852 [datastore.py:open_for_write():77] open: D:\Logiciel_école\GitHub\AIBSIF\src\model\wandb\run-20220323_172814-1olf1kr5\run-1olf1kr5.wandb
2022-03-23 17:28:24,231 DEBUG   SenderThread:22852 [sender.py:send():235] send: header
2022-03-23 17:28:24,231 DEBUG   SenderThread:22852 [sender.py:send():235] send: run
2022-03-23 17:28:24,480 ERROR   SenderThread:22852 [internal_api.py:execute():143] 404 response executing GraphQL.
2022-03-23 17:28:24,481 ERROR   SenderThread:22852 [internal_api.py:execute():144] {"errors":[{"message":"project not found","path":["upsertBucket"]}],"data":{"upsertBucket":null}}
2022-03-23 17:28:25,233 INFO    WriterThread:22852 [datastore.py:close():281] close: D:\Logiciel_école\GitHub\AIBSIF\src\model\wandb\run-20220323_172814-1olf1kr5\run-1olf1kr5.wandb
2022-03-23 17:28:25,246 INFO    HandlerThread:22852 [handler.py:finish():778] shutting down handler
2022-03-23 17:28:25,246 ERROR   MainThread:22852 [internal.py:wandb_internal():167] Thread SenderThread:
Traceback (most recent call last):
  File "d:\python\lib\site-packages\wandb\sdk\lib\retry.py", line 102, in __call__
    result = self._call_fn(*args, **kwargs)
  File "d:\python\lib\site-packages\wandb\sdk\internal\internal_api.py", line 146, in execute
    six.reraise(*sys.exc_info())
  File "d:\python\lib\site-packages\six.py", line 719, in reraise
    raise value
  File "d:\python\lib\site-packages\wandb\sdk\internal\internal_api.py", line 140, in execute
    return self.client.execute(*args, **kwargs)
  File "d:\python\lib\site-packages\wandb\vendor\gql-0.2.0\wandb_gql\client.py", line 52, in execute
    result = self._get_result(document, *args, **kwargs)
  File "d:\python\lib\site-packages\wandb\vendor\gql-0.2.0\wandb_gql\client.py", line 60, in _get_result
    return self.transport.execute(document, *args, **kwargs)
  File "d:\python\lib\site-packages\wandb\vendor\gql-0.2.0\wandb_gql\transport\requests.py", line 39, in execute
    request.raise_for_status()
  File "C:\Users\theo-\AppData\Roaming\Python\Python39\site-packages\requests\models.py", line 953, in raise_for_status
    raise HTTPError(http_error_msg, response=self)
requests.exceptions.HTTPError: 404 Client Error: Not Found for url: https://api.wandb.ai/graphql

During handling of the above exception, another exception occurred:

Traceback (most recent call last):
  File "d:\python\lib\site-packages\wandb\apis\normalize.py", line 24, in wrapper
    return func(*args, **kwargs)
  File "d:\python\lib\site-packages\wandb\sdk\internal\internal_api.py", line 1296, in upsert_run
    response = self.gql(mutation, variable_values=variable_values, **kwargs)
  File "d:\python\lib\site-packages\wandb\sdk\lib\retry.py", line 118, in __call__
    if not check_retry_fn(e):
  File "d:\python\lib\site-packages\wandb\util.py", line 872, in no_retry_auth
    raise CommError("Permission denied, ask the project owner to grant you access")
wandb.errors.CommError: Permission denied, ask the project owner to grant you access

During handling of the above exception, another exception occurred:

Traceback (most recent call last):
  File "d:\python\lib\site-packages\wandb\sdk\internal\internal_util.py", line 54, in run
    self._run()
  File "d:\python\lib\site-packages\wandb\sdk\internal\internal_util.py", line 105, in _run
    self._process(record)
  File "d:\python\lib\site-packages\wandb\sdk\internal\internal.py", line 312, in _process
    self._sm.send(record)
  File "d:\python\lib\site-packages\wandb\sdk\internal\sender.py", line 237, in send
    send_handler(record)
  File "d:\python\lib\site-packages\wandb\sdk\internal\sender.py", line 695, in send_run
    self._init_run(run, config_value_dict)
  File "d:\python\lib\site-packages\wandb\sdk\internal\sender.py", line 719, in _init_run
    server_run, inserted = self._api.upsert_run(
  File "d:\python\lib\site-packages\wandb\apis\normalize.py", line 62, in wrapper
    six.reraise(CommError, CommError(message, err), sys.exc_info()[2])
  File "d:\python\lib\site-packages\six.py", line 718, in reraise
    raise value.with_traceback(tb)
  File "d:\python\lib\site-packages\wandb\apis\normalize.py", line 24, in wrapper
    return func(*args, **kwargs)
  File "d:\python\lib\site-packages\wandb\sdk\internal\internal_api.py", line 1296, in upsert_run
    response = self.gql(mutation, variable_values=variable_values, **kwargs)
  File "d:\python\lib\site-packages\wandb\sdk\lib\retry.py", line 118, in __call__
    if not check_retry_fn(e):
  File "d:\python\lib\site-packages\wandb\util.py", line 872, in no_retry_auth
    raise CommError("Permission denied, ask the project owner to grant you access")
wandb.errors.CommError: Permission denied, ask the project owner to grant you access
2022-03-23 17:28:27,434 INFO    MainThread:22852 [internal.py:handle_exit():82] Internal process exited
